[2023-03-31T15:20:31.651+0500] {taskinstance.py:1084} INFO - Dependencies all met for dep_context=non-requeueable deps ti=<TaskInstance: my_Scraping_Dag.show_data manual__2023-03-31T10:17:01.290774+00:00 [queued]>
[2023-03-31T15:20:31.661+0500] {taskinstance.py:1084} INFO - Dependencies all met for dep_context=requeueable deps ti=<TaskInstance: my_Scraping_Dag.show_data manual__2023-03-31T10:17:01.290774+00:00 [queued]>
[2023-03-31T15:20:31.662+0500] {taskinstance.py:1282} INFO - 
--------------------------------------------------------------------------------
[2023-03-31T15:20:31.662+0500] {taskinstance.py:1283} INFO - Starting attempt 1 of 1
[2023-03-31T15:20:31.662+0500] {taskinstance.py:1284} INFO - 
--------------------------------------------------------------------------------
[2023-03-31T15:20:31.680+0500] {taskinstance.py:1303} INFO - Executing <Task(PythonOperator): show_data> on 2023-03-31 10:17:01.290774+00:00
[2023-03-31T15:20:31.697+0500] {standard_task_runner.py:55} INFO - Started process 1423 to run task
[2023-03-31T15:20:31.707+0500] {standard_task_runner.py:82} INFO - Running: ['airflow', 'tasks', 'run', 'my_Scraping_Dag', 'show_data', 'manual__2023-03-31T10:17:01.290774+00:00', '--job-id', '65', '--raw', '--subdir', 'DAGS_FOLDER/AirFlow_Task.py', '--cfg-path', '/tmp/tmpafi6sl1x']
[2023-03-31T15:20:31.709+0500] {standard_task_runner.py:83} INFO - Job 65: Subtask show_data
[2023-03-31T15:20:31.805+0500] {task_command.py:388} INFO - Running <TaskInstance: my_Scraping_Dag.show_data manual__2023-03-31T10:17:01.290774+00:00 [running]> on host Jamshaid-PC.localdomain
[2023-03-31T15:20:31.875+0500] {taskinstance.py:1509} INFO - Exporting the following env vars:
AIRFLOW_CTX_DAG_EMAIL=jamshaid.afzal@tmcltd.com
AIRFLOW_CTX_DAG_OWNER=jamshaid
AIRFLOW_CTX_DAG_ID=my_Scraping_Dag
AIRFLOW_CTX_TASK_ID=show_data
AIRFLOW_CTX_EXECUTION_DATE=2023-03-31T10:17:01.290774+00:00
AIRFLOW_CTX_TRY_NUMBER=1
AIRFLOW_CTX_DAG_RUN_ID=manual__2023-03-31T10:17:01.290774+00:00
[2023-03-31T15:20:33.522+0500] {taskinstance.py:1775} ERROR - Task failed with exception
Traceback (most recent call last):
  File "/home/jamshaid/.local/lib/python3.10/site-packages/gspread/client.py", line 150, in open
    properties = finditem(
  File "/home/jamshaid/.local/lib/python3.10/site-packages/gspread/utils.py", line 133, in finditem
    return next(item for item in seq if func(item))
StopIteration

During handling of the above exception, another exception occurred:

Traceback (most recent call last):
  File "/usr/local/lib/python3.10/dist-packages/airflow/operators/python.py", line 175, in execute
    return_value = self.execute_callable()
  File "/usr/local/lib/python3.10/dist-packages/airflow/operators/python.py", line 192, in execute_callable
    return self.python_callable(*self.op_args, **self.op_kwargs)
  File "/mnt/c/dags/AirFlow_Task.py", line 57, in show_data
    sh = gc.open('BathBombScraper').sheet1
  File "/home/jamshaid/.local/lib/python3.10/site-packages/gspread/client.py", line 160, in open
    raise SpreadsheetNotFound
gspread.exceptions.SpreadsheetNotFound
[2023-03-31T15:20:33.539+0500] {taskinstance.py:1321} INFO - Marking task as FAILED. dag_id=my_Scraping_Dag, task_id=show_data, execution_date=20230331T101701, start_date=20230331T102031, end_date=20230331T102033
[2023-03-31T15:20:33.570+0500] {standard_task_runner.py:100} ERROR - Failed to execute job 65 for task show_data (; 1423)
[2023-03-31T15:20:33.591+0500] {local_task_job.py:212} INFO - Task exited with return code 1
[2023-03-31T15:20:33.630+0500] {taskinstance.py:2591} INFO - Skipping mini scheduling run due to exception: SELECT dag_run.state AS dag_run_state, dag_run.id AS dag_run_id, dag_run.dag_id AS dag_run_dag_id, dag_run.queued_at AS dag_run_queued_at, dag_run.execution_date AS dag_run_execution_date, dag_run.start_date AS dag_run_start_date, dag_run.end_date AS dag_run_end_date, dag_run.run_id AS dag_run_run_id, dag_run.creating_job_id AS dag_run_creating_job_id, dag_run.external_trigger AS dag_run_external_trigger, dag_run.run_type AS dag_run_run_type, dag_run.conf AS dag_run_conf, dag_run.data_interval_start AS dag_run_data_interval_start, dag_run.data_interval_end AS dag_run_data_interval_end, dag_run.last_scheduling_decision AS dag_run_last_scheduling_decision, dag_run.dag_hash AS dag_run_dag_hash, dag_run.log_template_id AS dag_run_log_template_id, dag_run.updated_at AS dag_run_updated_at 
FROM dag_run 
WHERE dag_run.dag_id = ? AND dag_run.run_id = ?
Traceback (most recent call last):
  File "/usr/local/lib/python3.10/dist-packages/sqlalchemy/engine/base.py", line 1900, in _execute_context
    self.dialect.do_execute(
  File "/usr/local/lib/python3.10/dist-packages/sqlalchemy/engine/default.py", line 736, in do_execute
    cursor.execute(statement, parameters)
sqlite3.OperationalError: disk I/O error

The above exception was the direct cause of the following exception:

Traceback (most recent call last):
  File "/usr/local/lib/python3.10/dist-packages/airflow/models/taskinstance.py", line 2556, in schedule_downstream_tasks
    ).one()
  File "/usr/local/lib/python3.10/dist-packages/sqlalchemy/orm/query.py", line 2870, in one
    return self._iter().one()
  File "/usr/local/lib/python3.10/dist-packages/sqlalchemy/orm/query.py", line 2916, in _iter
    result = self.session.execute(
  File "/usr/local/lib/python3.10/dist-packages/sqlalchemy/orm/session.py", line 1714, in execute
    result = conn._execute_20(statement, params or {}, execution_options)
  File "/usr/local/lib/python3.10/dist-packages/sqlalchemy/engine/base.py", line 1705, in _execute_20
    return meth(self, args_10style, kwargs_10style, execution_options)
  File "/usr/local/lib/python3.10/dist-packages/sqlalchemy/sql/elements.py", line 334, in _execute_on_connection
    return connection._execute_clauseelement(
  File "/usr/local/lib/python3.10/dist-packages/sqlalchemy/engine/base.py", line 1572, in _execute_clauseelement
    ret = self._execute_context(
  File "/usr/local/lib/python3.10/dist-packages/sqlalchemy/engine/base.py", line 1943, in _execute_context
    self._handle_dbapi_exception(
  File "/usr/local/lib/python3.10/dist-packages/sqlalchemy/engine/base.py", line 2124, in _handle_dbapi_exception
    util.raise_(
  File "/usr/local/lib/python3.10/dist-packages/sqlalchemy/util/compat.py", line 211, in raise_
    raise exception
  File "/usr/local/lib/python3.10/dist-packages/sqlalchemy/engine/base.py", line 1900, in _execute_context
    self.dialect.do_execute(
  File "/usr/local/lib/python3.10/dist-packages/sqlalchemy/engine/default.py", line 736, in do_execute
    cursor.execute(statement, parameters)
sqlalchemy.exc.OperationalError: (sqlite3.OperationalError) disk I/O error
[SQL: SELECT dag_run.state AS dag_run_state, dag_run.id AS dag_run_id, dag_run.dag_id AS dag_run_dag_id, dag_run.queued_at AS dag_run_queued_at, dag_run.execution_date AS dag_run_execution_date, dag_run.start_date AS dag_run_start_date, dag_run.end_date AS dag_run_end_date, dag_run.run_id AS dag_run_run_id, dag_run.creating_job_id AS dag_run_creating_job_id, dag_run.external_trigger AS dag_run_external_trigger, dag_run.run_type AS dag_run_run_type, dag_run.conf AS dag_run_conf, dag_run.data_interval_start AS dag_run_data_interval_start, dag_run.data_interval_end AS dag_run_data_interval_end, dag_run.last_scheduling_decision AS dag_run_last_scheduling_decision, dag_run.dag_hash AS dag_run_dag_hash, dag_run.log_template_id AS dag_run_log_template_id, dag_run.updated_at AS dag_run_updated_at 
FROM dag_run 
WHERE dag_run.dag_id = ? AND dag_run.run_id = ?]
[parameters: ('my_Scraping_Dag', 'manual__2023-03-31T10:17:01.290774+00:00')]
(Background on this error at: https://sqlalche.me/e/14/e3q8)
